# 三十七 异常处理
异常是指程序错误的信号；一旦出现异常程序就会立即终止，出现异常之后的代码均不会运行。

为了增强程序的健壮性，即使发生错误程序也不会终止程序。而是要将异常捕获并记录错误信息到日志中

## 37.1 异常会有三个特征
1. 异常追踪信息
2. 异常类型

|异常名称|描述|
|:---:|:---:|
|`BaseException`|所有异常的基类|
|`SystemExit`|解释器请求退出|
|`KeyboardInterrupt`|用户中断执行|
|`Exception`|常规错误的基类|
|`StopIteration`|迭代器没有更多的值|
|`GeneratorExit`|生成器(generator)发生异常来通知退出|
|`StandardError`|所有的内建标准异常的基类|
|`ArithmeticError`|所有数值计算错误的基类|
|`FloatingPointError`|浮点计算错误|
|`OverflowError`|数值运算超出最大限制|
|`ZeroDivisionError`|除(或取模)零 (所有数据类型)|
|`AssertionError`|断言语句失败|
|`AttributeError`|对象没有这个属性|
|`EOFError`|没有内建输入,到达EOF 标记|
|`EnvironmentError`|操作系统错误的基类|
|`IOError`|输入/输出操作失败|
|`OSError`|操作系统错误|
|`WindowsError`|系统调用失败|
|`ImportError`|导入模块/对象失败|
|`LookupError`|无效数据查询的基类|
|`IndexError`|序列中没有此索引(index)|
|`KeyError`|映射中没有这个键|
|`MemoryError`|内存溢出错误(对于Python 解释器不是致命的)|
|`NameError`|未声明/初始化对象 (没有属性)|
|`UnboundLocalError`|访问未初始化的本地变量|
|`ReferenceError`|弱引用(Weak reference)试图访问已经垃圾回收了的对象|
|`RuntimeError`|一般的运行时错误|
|`NotImplementedError`|尚未实现的方法|
|`SyntaxError`|Python 语法错误|
|`IndentationError`|缩进错误|
|`TabError`|Tab 和空格混用|
|`SystemError`|一般的解释器系统错误|
|`TypeError`|对类型无效的操作|
|`ValueError`|传入无效的参数|
|`UnicodeError`|Unicode 相关的错误|
|`UnicodeDecodeError`|Unicode 解码时的错误|
|`UnicodeEncodeError`|Unicode 编码时错误|
|`UnicodeTranslateError`|Unicode 转换时错误|
|`Warning`|警告的基类|
|`DeprecationWarning`|关于被弃用的特征的警告|
|`FutureWarning`|关于构造将来语义会有改变的警告|
|`OverflowWarning`|旧的关于自动提升为长整型(long)的警告|
|`PendingDeprecationWarning`|关于特性将会被废弃的警告|
|`RuntimeWarning`|可疑的运行时行为(runtime behavior)的警告|
|`SyntaxWarning`|可疑的语法的警告|
|`UserWarning`|用户代码生成的警告|

3. 异常信息

## 37.2 异常的来源
1. 语法错误(`SyntaxError`) 
2. 逻辑错误
    > 1. 可预知的错误
    > 2. 不可预知的错误

## 37.3 错误捕获(捕获不可预知的错误)
```python
try:
    可能发生错误的代码
except 异常类型1 as e:
    # e: 错误信息
    发生异常执行的代码
except 异常类型2 as e:
    # e: 错误信息
    发生异常执行的代码
except (异常类型3, 异常类型4, ..., 异常类型n) as e:
    # e: 错误信息
    发生异常执行的代码
else:
    未发生异常执行的代码
finally:
    # 通常定义清理系统资源的操作
    无论错误是否发生都会运行
```
> 1. `e`: 是错误的信息
> 2. `try`: 必须跟`except`一起使用或和`finally`一起使用
> 3. `finally`: 通常定义系统资源清理的操作
> 4. `except`: 可以有多个捕捉多个错误，也可以使用一个捕捉多个错误
> 5. 多个`except`只执行一个

## 37.4 错误处理示例

1. **`try-except`**
    ```python
    print("start....")
    try:
        print("====111====")
        l = [1,2,3]
        # a = l[4]
        print("====222====")
        # aaa
        print("====333====")
        dic = {'a':1, "b": 2}
        dic['c']
    except IndexError as e:
        print("发生异常，信息为: ", e)
    except NameError as e:
        print("发生异常，异常信息为：", e)
    except KeyError as e:
        print("发生异常，异常信息为：", e)
    except Exception as e:  # Exception是常规错误异常的基类
        print("发生异常，异常信息为：", e)
    print("end....")
    ```
2. **`try-except-else`**
    ```python
    try:
        print("====111====")
        l = [1,2,3]
        a = l[4]
        print("====222====")
        aaa
        print("====333====")
        dic = {'a':1, "b": 2}
        dic['c']
    except Exception as e:  # Exception是常规错误异常的基类
        print("发生异常，异常信息为：", e)
    else:
        print("未发生错误")
    ```
3. **`try-except-finally`**
    ```python
    try:
        print("====111====")
        l = [1,2,3]
        a = l[4]
        print("====222====")
        aaa
        print("====333====")
        dic = {'a':1, "b": 2}
        dic['c']
    except Exception as e:  # Exception是常规错误异常的基类
        print("发生异常，异常信息为：", e)
    else:
        print("未发生错误")
    finally:
        print("预定义清理操作")
    ```
4. **`try-finally`**
    ```python
    try:
        print("====111====")
        l = [1,2,3]
        a = l[4]
        print("====222====")
        aaa
        print("====333====")
        dic = {'a':1, "b": 2}
        dic['c']
    finally:
        print("预定义清理操作")
    ```


